<?xml version="1.0" ?>
<!-- =================================================================================== -->
<!-- |    This document was autogenerated by xacro from /home/chinh/autoxing/src/ax6112_ur5_struct/config/ax6112_ur5_kinect.urdf.xacro | -->
<!-- |    EDITING THIS FILE BY HAND IS NOT RECOMMENDED                                 | -->
<!-- =================================================================================== -->
<robot name="ur5">
    <link name="base_footprint" />
    <link name="chassis">
        <inertial>
            <origin rpy="0 0 0" xyz="0.000149481705181087 -0.000120539934038988 0.152123091903942" />
            <mass value="116.0" />
            <inertia ixx="2.0609325089599997" ixy="0.0" ixz="0.0" iyy="4.34999826" iyz="0.0" izz="5.54093111696" />
        </inertial>
        <visual>
            <origin rpy="0 0 0" xyz="0 0 0" />
            <geometry>
                <mesh filename="package://autoxing/meshes/base_link.STL" />
            </geometry>
            <material name="">
                <color rgba="0.792156862745098 0.819607843137255 0.933333333333333 1" />
            </material>
        </visual>
        <collision>
            <origin rpy="0 0 0" xyz="0 0 0" />
            <geometry>
                <mesh filename="package://autoxing/meshes/base_link.STL" />
            </geometry>
        </collision>
    </link>
    <joint name="base_link_it" type="fixed">
        <origin rpy="0 0 0" xyz="0 0 0" />
        <parent link="base_footprint" />
        <child link="chassis" />
        <axis xyz="0 0 0" />
    </joint>
    <joint name="mir_struct_joint" type="fixed">
        <parent link="chassis" />
        <child link="part_down" />
        <origin rpy="0.0 0.0 0.0" xyz="0.0 0.0 0.20" />
    </joint>
    <link name="part_down">
        <inertial>
            <origin rpy="4.71238898038 1.57079632679 1.57079632679" xyz="0 0 0.3278534031" />
            <mass value="3.349376" />
            <inertia ixx="0.432077541" ixy="0" ixz="0" iyy="0.369249471" iyz="0" izz="0.179676981" />
        </inertial>
        <visual>
            <origin rpy="0 0 0" xyz="0 0 0" />
            <geometry>
                <mesh filename="package://ax6112/meshes/structure/visual/v1/part_down.stl" scale="0.65 0.65 0.5" />
            </geometry>
        </visual>
        <collision>
            <origin rpy="0 0 0" xyz="0 0 0" />
            <geometry>
                <mesh filename="package://ax6112/meshes/structure/collision/v1/part_down.stl" scale="0.65 0.65 0.5" />
            </geometry>
        </collision>
    </link>
    <gazebo reference="part_down">
        <material>Gazebo/Grey</material>
        <plugin name="gazebo_ros_control">
            <robotNamespace>/</robotNamespace>
        </plugin>
    </gazebo>
    <link name="part_up">
        <inertial>
            <origin rpy="4.71238898038 1.57079632679 1.57079632679" xyz="0 0 0.3535849057" />
            <mass value="4.64704" />
            <inertia ixx="0.549473755" ixy="0" ixz="0" iyy="0.436580833" iyz="0" izz="0.245971089" />
        </inertial>
        <visual>
            <origin rpy="0 0 0" xyz="0 0 0" />
            <geometry>
                <mesh filename="package://ax6112/meshes/structure/visual/v1/part_up.stl" scale="0.65 0.65 0.5" />
            </geometry>
        </visual>
        <collision>
            <origin rpy="0 0 0" xyz="0 0 0" />
            <geometry>
                <mesh filename="package://ax6112/meshes/structure/collision/v1/part_up.stl" scale="0.65 0.65 0.5" />
            </geometry>
        </collision>
    </link>
    <gazebo reference="part_up">
        <material>Gazebo/Grey</material>
    </gazebo>
    <link name="pedestal">
        <inertial>
            <origin rpy="4.71238898038 1.57079632679 0" xyz="0 0 0.1532210441" />
            <mass value="2.354023413" />
            <inertia ixx="0.049542988" ixy="0" ixz="0" iyy="0.042530187" iyz="0" izz="0.020198776" />
        </inertial>
        <visual>
            <origin rpy="0 0 0" xyz="0 0 0" />
            <geometry>
                <mesh filename="package://ax6112/meshes/structure/visual/v1/pedestal.stl" scale="0.8 1 0.5" />
            </geometry>
        </visual>
        <collision>
            <origin rpy="0 0 0" xyz="0 0 0" />
            <geometry>
                <mesh filename="package://ax6112/meshes/structure/collision/v1/pedestal.stl" scale="0.8 1 0.5" />
            </geometry>
        </collision>
    </link>
    <gazebo reference="pedestal">
        <material>Gazebo/Grey</material>
    </gazebo>
    <joint name="structure_vertical_joint" type="fixed">
        <origin rpy="0 0 0" xyz="0 0 0.14" />
        <parent link="part_down" />
        <child link="part_up" />
    </joint>
    <joint name="Tischaufbau_joint" type="fixed">
        <origin rpy="0 0 0" xyz="0 0 0.22" />
        <parent link="part_up" />
        <child link="pedestal" />
    </joint>
    <joint name="Tischaufbau_base_joint" type="fixed">
        <origin rpy="0 0 0" xyz="0 0 0.2492" />
        <parent link="pedestal" />
        <child link="pedestal_surface" />
    </joint>
    <link name="pedestal_surface" />
    <!--WHEEL-->
    <link name="wheel_left">
        <inertial>
            <origin rpy="0 0 0" xyz="-1.38777878078145E-16 -7.97972798949331E-17 0.0399999999999999" />
            <mass value="1" />
            <inertia ixx="0.001061895408575" ixy="0.0" ixz="0.0" iyy="0.001061895408575" iyz="0.0" izz="0.001953125" />
        </inertial>
        <visual>
            <origin rpy="0 0 0" xyz="0 0 0" />
            <geometry>
                <cylinder length="0.05" radius="0.08" />
            </geometry>
            <material name="">
                <color rgba="0.792156862745098 0.819607843137255 0.933333333333333 1" />
            </material>
        </visual>
        <collision>
            <origin rpy="0 0 0" xyz="0 0 0" />
            <geometry>
                <cylinder length="0.05" radius="0.08" />
            </geometry>
        </collision>
    </link>
    <joint name="wheel_left_joint" type="continuous">
        <origin rpy="-1.5707963267949 0 0" xyz="0 0.160461283375568 0.001" />
        <parent link="chassis" />
        <child link="wheel_left" />
        <axis xyz="0 0 1" />
    </joint>
    <link name="wheel_right">
        <inertial>
            <origin rpy="0 0 0" xyz="-1.38777878078145E-17 1.04083408558608E-17 0.0399999999999999" />
            <mass value="1" />
            <inertia ixx="0.001061895408575" ixy="0.0" ixz="0.0" iyy="0.001061895408575" iyz="0.0" izz="0.001953125" />
        </inertial>
        <visual>
            <origin rpy="0 0 0" xyz="0 0 0" />
            <geometry>
                <cylinder length="0.05" radius="0.08" />
            </geometry>
            <material name="">
                <color rgba="0.792156862745098 0.819607843137255 0.933333333333333 1" />
            </material>
        </visual>
        <collision>
            <origin rpy="0 0 0" xyz="0 0 0" />
            <geometry>
                <cylinder length="0.05" radius="0.08" />
            </geometry>
        </collision>
    </link>
    <joint name="wheel_right_joint" type="continuous">
        <origin rpy="1.5707963267949 0 0" xyz="0 -0.160461283375569 0.001" />
        <parent link="chassis" />
        <child link="wheel_right" />
        <axis xyz="0 0 -1" />
    </joint>
    <link name="casterhub_front_left">
        <inertial>
            <origin rpy="0 0 0" xyz="0.00631384572851573 -0.00939402891827468 -7.51390670640402E-05" />
            <mass value="0.0507301916211751" />
            <inertia ixx="2.13076622334858E-05" ixy="-4.77213305526971E-12" ixz="-2.15459256741868E-07" iyy="2.12936580660824E-05" iyz="-3.18977689924232E-11" izz="9.21167172411273E-06" />
        </inertial>
        <visual>
            <origin rpy="0 0 0" xyz="0 0 0" />
            <geometry>
                <mesh filename="package://autoxing/meshes/casterhub_front_left.STL" />
            </geometry>
            <material name="">
                <color rgba="0.792156862745098 0.819607843137255 0.933333333333333 1" />
            </material>
        </visual>
        <collision>
            <origin rpy="0 0 0" xyz="0 0 0" />
            <geometry>
                <mesh filename="package://autoxing/meshes/casterhub_front_left.STL" />
            </geometry>
        </collision>
    </link>
    <joint name="casterhub_front_left_joint" type="continuous">
        <origin rpy="0 0 0" xyz="0.191588642505787 0.16140857130743 0.00300000000000051" />
        <parent link="chassis" />
        <child link="casterhub_front_left" />
        <axis xyz="0 0 1" />
        <dynamics damping="0.01" friction="0.0" />
    </joint>
    <link name="wheel_lf">
        <inertial>
            <origin rpy="0 0 0" xyz="2.77555756156289E-17 3.46944695195361E-17 0.0275000000000001" />
            <mass value="1" />
            <inertia ixx="0.001061895408575" ixy="0.0" ixz="0.0" iyy="0.001061895408575" iyz="0.0" izz="0.001953125" />
        </inertial>
        <visual>
            <origin rpy="0 0 0" xyz="0 0 0" />
            <geometry>
                <mesh filename="package://autoxing/meshes/wheel_lf.STL" />
            </geometry>
            <material name="">
                <color rgba="0.792156862745098 0.819607843137255 0.933333333333333 1" />
            </material>
        </visual>
        <collision>
            <origin rpy="0 0 0" xyz="0 0 0.025" />
            <geometry>
                <cylinder length="0.055" radius="0.0375" />
            </geometry>
        </collision>
    </link>
    <joint name="wheel_lf_joint" type="continuous">
        <origin rpy="-1.5707963267949 0 0" xyz="-0.0185912035639785 -0.036894016223973 -0.0450000000000003" />
        <parent link="casterhub_front_left" />
        <child link="wheel_lf" />
        <axis xyz="0 0 -1" />
    </joint>
    <link name="casterhub_front_right">
        <inertial>
            <origin rpy="0 0 0" xyz="0.00631384572851623 0.00939400352967251 -7.51390670643212E-05" />
            <mass value="0.0507301916211753" />
            <inertia ixx="2.13076622334862E-05" ixy="0" ixz="0" iyy="2.12936580660827E-05" iyz="0" izz="9.21167172411275E-06" />
        </inertial>
        <visual>
            <origin rpy="0 0 0" xyz="0 0 0" />
            <geometry>
                <mesh filename="package://autoxing/meshes/casterhub_front_right.STL" />
            </geometry>
            <material name="">
                <color rgba="0.792156862745098 0.819607843137255 0.933333333333333 1" />
            </material>
        </visual>
        <collision>
            <origin rpy="0 0 0" xyz="0 0 0" />
            <geometry>
                <mesh filename="package://autoxing/meshes/casterhub_front_right.STL" />
            </geometry>
        </collision>
    </link>
    <joint name="casterhub_front_right_joint" type="continuous">
        <origin rpy="0 0 0" xyz="0.191588642505786 -0.161408571307431 0.00300000000000041" />
        <parent link="chassis" />
        <child link="casterhub_front_right" />
        <axis xyz="0 0 1" />
        <dynamics damping="0.01" friction="0.0" />
    </joint>
    <link name="wheel_rf">
        <inertial>
            <origin rpy="0 0 0" xyz="-5.55111512312578E-17 -2.77555756156289E-17 0.0275" />
            <mass value="1" />
            <inertia ixx="0.001061895408575" ixy="0.0" ixz="0.0" iyy="0.001061895408575" iyz="0.0" izz="0.001953125" />
        </inertial>
        <visual>
            <origin rpy="0 0 0" xyz="0 0 0" />
            <geometry>
                <mesh filename="package://autoxing/meshes/wheel_rf.STL" />
            </geometry>
            <material name="">
                <color rgba="0.792156862745098 0.819607843137255 0.933333333333333 1" />
            </material>
        </visual>
        <collision>
            <origin rpy="0 0 0" xyz="0 0 0.025" />
            <geometry>
                <cylinder length="0.055" radius="0.0375" />
            </geometry>
        </collision>
    </link>
    <joint name="wheel_rf_joint" type="continuous">
        <origin rpy="1.5707963267949 0 0" xyz="-0.0185912035639783 0.0368940162239737 -0.0450000000000001" />
        <parent link="casterhub_front_right" />
        <child link="wheel_rf" />
        <axis xyz="0 0 1" />
    </joint>
    <link name="casterhub_back_left">
        <inertial>
            <origin rpy="0 0 0" xyz="-0.00631384572595789 -0.00939400352571207 -7.51390691109341E-05" />
            <mass value="0.0507301916238285" />
            <inertia ixx="2.13076622385357E-05" ixy="0" ixz="0" iyy="2.12936580714444E-05" iyz="0" izz="9.21167172497116E-06" />
        </inertial>
        <visual>
            <origin rpy="0 0 0" xyz="0 0 0" />
            <geometry>
                <mesh filename="package://autoxing/meshes/casterhub_back_left.STL" />
            </geometry>
            <material name="">
                <color rgba="0.792156862745098 0.819607843137255 0.933333333333333 1" />
            </material>
        </visual>
        <collision>
            <origin rpy="0 0 0" xyz="0 0 0" />
            <geometry>
                <mesh filename="package://autoxing/meshes/casterhub_back_left.STL" />
            </geometry>
        </collision>
    </link>
    <joint name="casterhub_back_left_joint" type="continuous">
        <origin rpy="0 0 3.14159" xyz="-0.191588642505784 0.15140857130743 0.00300000000000039" />
        <parent link="chassis" />
        <child link="casterhub_back_left" />
        <axis xyz="0 0 1" />
        <dynamics damping="0.01" friction="0.0" />
    </joint>
    <link name="wheel_lb">
        <inertial>
            <origin rpy="0 0 0" xyz="5.55111512312578E-17 2.42861286636753E-17 0.0275" />
            <mass value="1" />
            <inertia ixx="0.001061895408575" ixy="0.0" ixz="0.0" iyy="0.001061895408575" iyz="0.0" izz="0.001953125" />
        </inertial>
        <visual>
            <origin rpy="0 0 0" xyz="0 0 0" />
            <geometry>
                <mesh filename="package://autoxing/meshes/wheel_lb.STL" />
            </geometry>
            <material name="">
                <color rgba="0.792156862745098 0.819607843137255 0.933333333333333 1" />
            </material>
        </visual>
        <collision>
            <origin rpy="0 0 0" xyz="0 0 0.025" />
            <geometry>
                <cylinder length="0.055" radius="0.0375" />
            </geometry>
        </collision>
    </link>
    <joint name="wheel_lb_joint" type="continuous">
        <origin rpy="-1.5707963267949 0 0" xyz="0.0185912035639781 -0.0368940162239735 -0.0450000000000004" />
        <parent link="casterhub_back_left" />
        <child link="wheel_lb" />
        <axis xyz="0 0 -1" />
    </joint>
    <link name="casterhub_back_right">
        <inertial>
            <origin rpy="0 0 0" xyz="-0.00631384572595783 0.00939402892223568 -7.51390691110208E-05" />
            <mass value="0.0507301916238286" />
            <inertia ixx="2.1307662238536E-05" ixy="-4.77268550032231E-12" ixz="2.15459261528391E-07" iyy="2.12936580714447E-05" iyz="3.19056366466023E-11" izz="9.21167172497116E-06" />
        </inertial>
        <visual>
            <origin rpy="0 0 0" xyz="0 0 0" />
            <geometry>
                <mesh filename="package://autoxing/meshes/casterhub_back_right.STL" />
            </geometry>
            <material name="">
                <color rgba="0.792156862745098 0.819607843137255 0.933333333333333 1" />
            </material>
        </visual>
        <collision>
            <origin rpy="0 0 0" xyz="0 0 0" />
            <geometry>
                <mesh filename="package://autoxing/meshes/casterhub_back_right.STL" />
            </geometry>
        </collision>
    </link>
    <joint name="casterhub_back_right_joint" type="continuous">
        <origin rpy="0 0 3.14159" xyz="-0.191588642505784 -0.151408571307431 0.00300000000000018" />
        <parent link="chassis" />
        <child link="casterhub_back_right" />
        <axis xyz="0 0 1" />
        <dynamics damping="0.01" friction="0.0" />
    </joint>
    <link name="wheel_rb">
        <inertial>
            <origin rpy="0 0 0" xyz="-3.33066907387547E-16 2.84494650060196E-16 0.0275" />
            <mass value="1" />
            <inertia ixx="0.001061895408575" ixy="0.0" ixz="0.0" iyy="0.001061895408575" iyz="0.0" izz="0.001953125" />
        </inertial>
        <visual>
            <origin rpy="0 0 0" xyz="0 0 0" />
            <geometry>
                <mesh filename="package://autoxing/meshes/wheel_rb.STL" />
            </geometry>
            <material name="">
                <color rgba="0.792156862745098 0.819607843137255 0.933333333333333 1" />
            </material>
        </visual>
        <collision>
            <origin rpy="0 0 0" xyz="0 0 0.025" />
            <geometry>
                <cylinder length="0.055" radius="0.0375" />
            </geometry>
        </collision>
    </link>
    <joint name="wheel_rb_joint" type="continuous">
        <origin rpy="1.5707963267949 0 0" xyz="0.0185912035639779 0.0368940162239737 -0.0450000000000001" />
        <parent link="casterhub_back_right" />
        <child link="wheel_rb" />
        <axis xyz="0 0 1" />
    </joint>
    <link name="lidar">
        <inertial>
            <origin rpy="0 0 0" xyz="-2.77555756156289E-17 0 -0.005" />
            <mass value="0.000785398163397448" />
            <inertia ixx="1.14537232162128E-08" ixy="0" ixz="0" iyy="1.14537232162128E-08" iyz="0" izz="9.8174770424681E-09" />
        </inertial>
        <visual>
            <origin rpy="0 0 0" xyz="0 0 0" />
            <geometry>
                <mesh filename="package://autoxing/meshes/lidar.STL" />
            </geometry>
            <material name="">
                <color rgba="0.792156862745098 0.819607843137255 0.933333333333333 1" />
            </material>
        </visual>
        <collision>
            <origin rpy="0 0 0" xyz="0 0 0" />
            <geometry>
                <mesh filename="package://autoxing/meshes/lidar.STL" />
            </geometry>
        </collision>
    </link>
    <joint name="lidar_joint" type="fixed">
        <origin rpy="0 0 0" xyz="0.00671416680612409 0.00186793926091405 0.158" />
        <parent link="chassis" />
        <child link="lidar" />
        <axis xyz="0 0 0" />
    </joint>
    <!--imu_sensor-->
    <link name="imu_link">
        <inertial>
            <origin rpy="0 0 0" xyz="-2.77555756156289E-17 0 -0.005" />
            <mass value="0.000785398163397448" />
            <inertia ixx="1.14537232162128E-08" ixy="0" ixz="-3.39253103278279E-24" iyy="1.14537232162128E-08" iyz="-1.03950157856018E-23" izz="9.8174770424681E-09" />
        </inertial>
        <visual>
            <origin rpy="0 0 0" xyz="0 0 0" />
            <geometry>
                <mesh filename="package://autoxing/meshes/lidar.STL" />
            </geometry>
            <material name="">
                <color rgba="0.792156862745098 0.819607843137255 0.933333333333333 1" />
            </material>
        </visual>
        <collision>
            <origin rpy="0 0 0" xyz="0 0 0" />
            <geometry>
                <mesh filename="package://autoxing/meshes/lidar.STL" />
            </geometry>
        </collision>
    </link>
    <joint name="camera_low_joint" type="fixed">
        <origin rpy="0 0 0" xyz="0.3 0 0.3" />
        <parent link="chassis" />
        <child link="camera_low" />
        <axis xyz="0 0 1" />
    </joint>
    <link name="camera_low">
        <visual>
            <origin rpy="0 0 0" xyz="0 0 0" />
            <geometry>
                <mesh filename="package://autoxing/meshes/kinect.dae" />
            </geometry>
            <material name="dark_grey">
                <color rgba="0.3 0.3 0.3 1" />
            </material>
        </visual>
    </link>
    <gazebo reference="camera_low">
        <sensor name="camera" type="depth">
            <always_on>true</always_on>
            <update_rate>20</update_rate>
            <camera>
                <horizontal_fov>1.0471975512</horizontal_fov>
                <image>
                    <!-- <width>1024</width> -->
                    <!-- <height>1024</height> -->
                    <format>R8G8B8</format>
                    <width>640</width>
                    <height>480</height>
                </image>
                <clip>
                    <near>0.05</near>
                    <!-- <far>4</far> -->
                    <far>8.0</far>
                </clip>
            </camera>
            <plugin filename="libgazebo_ros_openni_kinect.so" name="camera_low_plugin">
                <!-- <baseline>0.2</baseline> -->
                <baseline>0.1</baseline>
                <alwaysOn>true</alwaysOn>
                <!-- Keep this zero, update_rate in the parent <sensor> tag
            will control the frame rate. -->
                <updateRate>0.0</updateRate>
                <cameraName>camera_ir_low</cameraName>
                <imageTopicName>/camera_low/color/image_raw</imageTopicName>
                <cameraInfoTopicName>/camera_low/color/camera_info</cameraInfoTopicName>
                <depthImageTopicName>/camera_low/depth/image_raw</depthImageTopicName>
                <depthImageCameraInfoTopicName>/camera_low/depth/camera_info</depthImageCameraInfoTopicName>
                <pointCloudTopicName>/camera_low/depth/points</pointCloudTopicName>
                <frameName>camera_link1</frameName>
                <pointCloudCutoff>0.1</pointCloudCutoff>
                <pointCloudCutoffMax>1.0</pointCloudCutoffMax>
                <distortionK1>0</distortionK1>
                <distortionK2>0</distortionK2>
                <distortionK3>0</distortionK3>
                <distortionT1>0</distortionT1>
                <distortionT2>0</distortionT2>
                <CxPrime>0</CxPrime>
                <Cx>0</Cx>
                <Cy>0</Cy>
                <focalLength>0</focalLength>
                <hackBaseline>0</hackBaseline>
            </plugin>
        </sensor>
    </gazebo>
    <joint name="imu_joint" type="fixed">
        <origin rpy="0 0 0" xyz="0.00671416680612409 0.00186793926091405 0.1" />
        <parent link="chassis" />
        <child link="imu_link" />
        <axis xyz="0 0 0" />
    </joint>
    <gazebo reference="chassis">
        <material>Gazebo/Turquoise</material>
    </gazebo>
    <gazebo reference="wheel_left">
        <mu1>200.0</mu1>
        <mu2>200.0</mu2>
        <kp>10000000</kp>
        <kd>1.0</kd>
        <material>Gazebo/FlatBlack</material>
    </gazebo>
    <gazebo reference="wheel_right">
        <mu1>200.0</mu1>
        <mu2>200.0</mu2>
        <kp>10000000</kp>
        <kd>1.0</kd>
        <material>Gazebo/FlatBlack</material>
    </gazebo>
    <gazebo reference="lidar">
        <material>Gazebo/Green</material>
    </gazebo>
    <gazebo reference="wheel_lf">
        <mu1>0.09</mu1>
        <mu2>0.09</mu2>
        <kp>10000000</kp>
        <kd>1.0</kd>
        <material>Gazebo/FlatBlack</material>
    </gazebo>
    <gazebo reference="wheel_rf">
        <mu1>0.09</mu1>
        <mu2>0.09</mu2>
        <kp>10000000</kp>
        <kd>1.0</kd>
        <material>Gazebo/FlatBlack</material>
    </gazebo>
    <gazebo reference="wheel_lb">
        <mu1>0.09</mu1>
        <mu2>0.09</mu2>
        <kp>10000000</kp>
        <kd>1.0</kd>
        <material>Gazebo/FlatBlack</material>
    </gazebo>
    <gazebo reference="wheel_rb">
        <mu1>0.09</mu1>
        <mu2>0.09</mu2>
        <kp>10000000</kp>
        <kd>1.0</kd>
        <material>Gazebo/FlatBlack</material>
    </gazebo>
    <!-- adding diff drive -->
    <gazebo>
        <plugin filename="libgazebo_ros_diff_drive.so" name="diff_drive_controller">
            <legacyMode>false</legacyMode>
            <alwaysOn>true</alwaysOn>
            <updateRate>5</updateRate>
            <leftJoint>wheel_left_joint</leftJoint>
            <rightJoint>wheel_right_joint</rightJoint>
            <wheelSeparation>0.445208</wheelSeparation>
            <wheelDiameter>0.16</wheelDiameter>
            <wheelTorque>10</wheelTorque>
            <publishTf>1</publishTf>
            <odometryFrame>odom</odometryFrame>
            <commandTopic>cmd_vel</commandTopic>
            <odometryTopic>odom</odometryTopic>
            <robotBaseFrame>base_footprint</robotBaseFrame>
            <wheelAcceleration>2.8</wheelAcceleration>
            <publishWheelJointState>true</publishWheelJointState>
            <publishWheelTF>false</publishWheelTF>
            <odometrySource>odom</odometrySource>
            <rosDebugLevel>Debug</rosDebugLevel>
        </plugin>
    </gazebo>
    <transmission name="left_wheel_trans">
        <type>transmission_interface/SimpleTransmission</type>
        <joint name="wheel_left_joint">
            <hardwareInterface>hardware_interface/VelocityJointInterface</hardwareInterface>
        </joint>
        <actuator name="left_wheel_motor">
            <hardwareInterface>hardware_interface/VelocityJointInterface</hardwareInterface>
            <mechanicalReduction>1</mechanicalReduction>
        </actuator>
    </transmission>
    <transmission name="right_wheel_trans">
        <type>transmission_interface/SimpleTransmission</type>
        <joint name="wheel_right_joint">
            <hardwareInterface>hardware_interface/VelocityJointInterface</hardwareInterface>
        </joint>
        <actuator name="right_wheel_motor">
            <hardwareInterface>hardware_interface/VelocityJointInterface</hardwareInterface>
            <mechanicalReduction>1</mechanicalReduction>
        </actuator>
    </transmission>
    <gazebo>
        <plugin filename="libgazebo_ros_p3d.so" name="p3d_base_controller">
            <alwaysOn>true</alwaysOn>
            <updateRate>50.0</updateRate>
            <bodyName>base_footprint</bodyName>
            <topicName>base_pose_ground_truth</topicName>
            <gaussianNoise>0.01</gaussianNoise>
            <frameName>map</frameName>
            <xyzOffsets>0 0 0</xyzOffsets>
            <rpyOffsets>0 0 0</rpyOffsets>
        </plugin>
    </gazebo>
    <gazebo>
        <plugin filename="libgazebo_ros_control.so" name="gazebo_ros_control">
            <controlPeriod>0.001</controlPeriod>
            <legacyModeNS>false</legacyModeNS>
        </plugin>
    </gazebo>
    <!-- hokuyo -->
    <gazebo reference="lidar">
        <sensor name="sensor" type="ray">
            <pose>0 0 0 0 0 0</pose>
            <visualize>false</visualize>
            <update_rate>40</update_rate>
            <ray>
                <scan>
                    <horizontal>
                        <samples>720</samples>
                        <resolution>1</resolution>
                        <min_angle>-1.570796</min_angle>
                        <max_angle>4.712388</max_angle>
                        <!-- 1.570796-->
                    </horizontal>
                </scan>
                <range>
                    <min>0.28</min>
                    <max>30.0</max>
                    <resolution>0.01</resolution>
                </range>
                <noise>
                    <type>gaussian</type>
                    <!-- Noise parameters based on published spec for Hokuyo laser
               achieving "+-30mm" accuracy at range < 10m.  A mean of 0.0m and
               stddev of 0.01m will put 99.7% of samples within 0.03m of the true
               reading. -->
                    <mean>0.0</mean>
                    <stddev>0.01</stddev>
                </noise>
            </ray>
            <plugin filename="libgazebo_ros_laser.so" name="hokuyo_node">
                <topicName>/laser/scan</topicName>
                <frameName>lidar</frameName>
            </plugin>
        </sensor>
    </gazebo>
    <!-- imu sensor -->
    <gazebo>
        <plugin filename="libgazebo_ros_imu.so" name="imu_plugin">
            <alwaysOn>true</alwaysOn>
            <bodyName>chassis</bodyName>
            <topicName>imu</topicName>
            <serviceName>imu_service</serviceName>
            <gaussianNoise>0.0</gaussianNoise>
            <updateRate>1.0</updateRate>
        </plugin>
    </gazebo>
    <gazebo reference="imu_link">
        <gravity>true</gravity>
        <sensor name="imu_sensor" type="imu">
            <always_on>true</always_on>
            <update_rate>100</update_rate>
            <visualize>true</visualize>
            <topic>__default_topic__</topic>
            <plugin filename="libgazebo_ros_imu_sensor.so" name="imu_plugin">
                <topicName>imu</topicName>
                <bodyName>imu_link</bodyName>
                <updateRateHZ>10.0</updateRateHZ>
                <gaussianNoise>0.0</gaussianNoise>
                <xyzOffset>0 0 0</xyzOffset>
                <rpyOffset>0 0 0</rpyOffset>
                <frameName>imu_link</frameName>
                <initialOrientationAsReference>false</initialOrientationAsReference>
            </plugin>
            <pose>0 0 0 0 0 0</pose>
        </sensor>
    </gazebo>
    <transmission name="trans_casterhub_front_left_joint">
        <type>transmission_interface/SimpleTransmission</type>
        <joint name="casterhub_front_left_joint">
            <hardwareInterface>hardware_interface/EffortJointInterface</hardwareInterface>
        </joint>
        <actuator name="casterhub_front_left_joint_motor">
            <hardwareInterface>hardware_interface/EffortJointInterface</hardwareInterface>
            <mechanicalReduction>1</mechanicalReduction>
        </actuator>
    </transmission>
    <transmission name="trans_wheel_lf_joint">
        <type>transmission_interface/SimpleTransmission</type>
        <joint name="wheel_lf_joint">
            <hardwareInterface>hardware_interface/EffortJointInterface</hardwareInterface>
        </joint>
        <actuator name="wheel_lf_joint_motor">
            <hardwareInterface>hardware_interface/EffortJointInterface</hardwareInterface>
            <mechanicalReduction>1</mechanicalReduction>
        </actuator>
    </transmission>
    <transmission name="trans_casterhub_front_right_joint">
        <type>transmission_interface/SimpleTransmission</type>
        <joint name="casterhub_front_right_joint">
            <hardwareInterface>hardware_interface/EffortJointInterface</hardwareInterface>
        </joint>
        <actuator name="casterhub_front_right_joint_motor">
            <hardwareInterface>hardware_interface/EffortJointInterface</hardwareInterface>
            <mechanicalReduction>1</mechanicalReduction>
        </actuator>
    </transmission>
    <transmission name="trans_wheel_rf_joint">
        <type>transmission_interface/SimpleTransmission</type>
        <joint name="wheel_rf_joint">
            <hardwareInterface>hardware_interface/EffortJointInterface</hardwareInterface>
        </joint>
        <actuator name="wheel_rf_joint_motor">
            <hardwareInterface>hardware_interface/EffortJointInterface</hardwareInterface>
            <mechanicalReduction>1</mechanicalReduction>
        </actuator>
    </transmission>
    <transmission name="trans_casterhub_back_left_joint">
        <type>transmission_interface/SimpleTransmission</type>
        <joint name="casterhub_back_left_joint">
            <hardwareInterface>hardware_interface/EffortJointInterface</hardwareInterface>
        </joint>
        <actuator name="casterhub_back_left_joint_motor">
            <hardwareInterface>hardware_interface/EffortJointInterface</hardwareInterface>
            <mechanicalReduction>1</mechanicalReduction>
        </actuator>
    </transmission>
    <transmission name="trans_wheel_lb_joint">
        <type>transmission_interface/SimpleTransmission</type>
        <joint name="wheel_lb_joint">
            <hardwareInterface>hardware_interface/EffortJointInterface</hardwareInterface>
        </joint>
        <actuator name="wheel_lb_joint_motor">
            <hardwareInterface>hardware_interface/EffortJointInterface</hardwareInterface>
            <mechanicalReduction>1</mechanicalReduction>
        </actuator>
    </transmission>
    <transmission name="trans_casterhub_back_right_joint">
        <type>transmission_interface/SimpleTransmission</type>
        <joint name="casterhub_back_right_joint">
            <hardwareInterface>hardware_interface/EffortJointInterface</hardwareInterface>
        </joint>
        <actuator name="casterhub_back_right_joint_motor">
            <hardwareInterface>hardware_interface/EffortJointInterface</hardwareInterface>
            <mechanicalReduction>1</mechanicalReduction>
        </actuator>
    </transmission>
    <transmission name="trans_wheel_rb_joint">
        <type>transmission_interface/SimpleTransmission</type>
        <joint name="wheel_rb_joint">
            <hardwareInterface>hardware_interface/EffortJointInterface</hardwareInterface>
        </joint>
        <actuator name="wheel_rb_joint_motor">
            <hardwareInterface>hardware_interface/EffortJointInterface</hardwareInterface>
            <mechanicalReduction>1</mechanicalReduction>
        </actuator>
    </transmission>
    <!-- UR5 AND GRIPPER -->
    <link name="base_link">
        <visual>
            <geometry>
                <mesh filename="package://ur_description/meshes/ur5/visual/base.dae" />
            </geometry>
            <material name="LightGrey">
                <color rgba="0.7 0.7 0.7 1.0" />
            </material>
        </visual>
        <collision>
            <geometry>
                <mesh filename="package://ur_description/meshes/ur5/collision/base.stl" />
            </geometry>
        </collision>
        <inertial>
            <mass value="4.0" />
            <origin rpy="0 0 0" xyz="0.0 0.0 0.0" />
            <inertia ixx="0.00443333156" ixy="0.0" ixz="0.0" iyy="0.00443333156" iyz="0.0" izz="0.0072" />
        </inertial>
    </link>
    <joint name="world_joint" type="fixed">
        <parent link="pedestal" />
        <child link="base_link" />
        <origin rpy="0.0 0.0 -1.58" xyz="0.0 0.0 0.13" />
    </joint>
    <joint name="shoulder_pan_joint" type="revolute">
        <parent link="base_link" />
        <child link="shoulder_link" />
        <origin rpy="0.0 0.0 -1.57" xyz="0.0 0.0 0.089159" />
        <axis xyz="0 0 1" />
        <limit effort="150.0" lower="-3.141592653589793" upper="3.141592653589793" velocity="3.15" />
        <dynamics damping="0.0" friction="0.0" />
    </joint>
    <link name="shoulder_link">
        <visual>
            <geometry>
                <mesh filename="package://ur_description/meshes/ur5/visual/shoulder.dae" />
            </geometry>
            <material name="LightGrey">
                <color rgba="0.7 0.7 0.7 1.0" />
            </material>
        </visual>
        <collision>
            <geometry>
                <mesh filename="package://ur_description/meshes/ur5/collision/shoulder.stl" />
            </geometry>
        </collision>
        <inertial>
            <mass value="0.01" />
            <origin rpy="0 0 0" xyz="0.0 0.0 0.0" />
            <inertia ixx="0.010267495893" ixy="0.0" ixz="0.0" iyy="0.010267495893" iyz="0.0" izz="0.00666" />
        </inertial>
    </link>
    <joint name="shoulder_lift_joint" type="revolute">
        <parent link="shoulder_link" />
        <child link="upper_arm_link" />
        <origin rpy="0.0 1.5707963267948966 0.0" xyz="0.0 0.13585 0.0" />
        <axis xyz="0 1 0" />
        <limit effort="150.0" lower="-3.141592653589793" upper="3.141592653589793" velocity="3.15" />
        <dynamics damping="0.0" friction="0.0" />
    </joint>
    <link name="upper_arm_link">
        <visual>
            <geometry>
                <mesh filename="package://ur_description/meshes/ur5/visual/upperarm.dae" />
            </geometry>
            <material name="LightGrey">
                <color rgba="0.7 0.7 0.7 1.0" />
            </material>
        </visual>
        <collision>
            <geometry>
                <mesh filename="package://ur_description/meshes/ur5/collision/upperarm.stl" />
            </geometry>
        </collision>
        <inertial>
            <mass value="0.01" />
            <origin rpy="0 0 0" xyz="0.0 0.0 0.28" />
            <inertia ixx="0.22689067591036005" ixy="0.0" ixz="0.0" iyy="0.22689067591036005" iyz="0.0" izz="0.0151074" />
        </inertial>
    </link>
    <joint name="elbow_joint" type="revolute">
        <parent link="upper_arm_link" />
        <child link="forearm_link" />
        <origin rpy="0.0 0.0 0.0" xyz="0.0 -0.1197 0.425" />
        <axis xyz="0 1 0" />
        <limit effort="150.0" lower="-3.141592653589793" upper="3.141592653589793" velocity="3.15" />
        <dynamics damping="0.0" friction="0.0" />
    </joint>
    <link name="forearm_link">
        <visual>
            <geometry>
                <mesh filename="package://ur_description/meshes/ur5/visual/forearm.dae" />
            </geometry>
            <material name="LightGrey">
                <color rgba="0.7 0.7 0.7 1.0" />
            </material>
        </visual>
        <collision>
            <geometry>
                <mesh filename="package://ur_description/meshes/ur5/collision/forearm.stl" />
            </geometry>
        </collision>
        <inertial>
            <mass value="0.01" />
            <origin rpy="0 0 0" xyz="0.0 0.0 0.196125" />
            <inertia ixx="0.03121679102890359" ixy="0.0" ixz="0.0" iyy="0.03121679102890359" iyz="0.0" izz="0.004095" />
        </inertial>
    </link>
    <joint name="wrist_1_joint" type="revolute">
        <parent link="forearm_link" />
        <child link="wrist_1_link" />
        <origin rpy="0.0 1.5707963267948966 0.0" xyz="0.0 0.0 0.39225" />
        <axis xyz="0 1 0" />
        <limit effort="28.0" lower="-3.141592653589793" upper="3.141592653589793" velocity="3.2" />
        <dynamics damping="0.0" friction="0.0" />
    </joint>
    <link name="wrist_1_link">
        <visual>
            <geometry>
                <mesh filename="package://ur_description/meshes/ur5/visual/wrist1.dae" />
            </geometry>
            <material name="LightGrey">
                <color rgba="0.7 0.7 0.7 1.0" />
            </material>
        </visual>
        <collision>
            <geometry>
                <mesh filename="package://ur_description/meshes/ur5/collision/wrist1.stl" />
            </geometry>
        </collision>
        <inertial>
            <mass value="0.01" />
            <origin rpy="0 0 0" xyz="0.0 0.093 0.0" />
            <inertia ixx="0.0025598989760400002" ixy="0.0" ixz="0.0" iyy="0.0025598989760400002" iyz="0.0" izz="0.0021942" />
        </inertial>
    </link>
    <joint name="wrist_2_joint" type="revolute">
        <parent link="wrist_1_link" />
        <child link="wrist_2_link" />
        <origin rpy="0.0 0.0 0.0" xyz="0.0 0.093 0.0" />
        <axis xyz="0 0 1" />
        <limit effort="28.0" lower="-3.141592653589793" upper="3.141592653589793" velocity="3.2" />
        <dynamics damping="0.0" friction="0.0" />
    </joint>
    <link name="wrist_2_link">
        <visual>
            <geometry>
                <mesh filename="package://ur_description/meshes/ur5/visual/wrist2.dae" />
            </geometry>
            <material name="LightGrey">
                <color rgba="0.7 0.7 0.7 1.0" />
            </material>
        </visual>
        <collision>
            <geometry>
                <mesh filename="package://ur_description/meshes/ur5/collision/wrist2.stl" />
            </geometry>
        </collision>
        <inertial>
            <mass value="0.01" />
            <origin rpy="0 0 0" xyz="0.0 0.0 0.09465" />
            <inertia ixx="0.0025598989760400002" ixy="0.0" ixz="0.0" iyy="0.0025598989760400002" iyz="0.0" izz="0.0021942" />
        </inertial>
    </link>
    <joint name="wrist_3_joint" type="revolute">
        <parent link="wrist_2_link" />
        <child link="wrist_3_link" />
        <origin rpy="0.0 0.0 0.0" xyz="0.0 0.0 0.09465" />
        <axis xyz="0 1 0" />
        <limit effort="28.0" lower="-3.141592653589793" upper="3.141592653589793" velocity="3.2" />
        <dynamics damping="0.0" friction="0.0" />
    </joint>
    <link name="wrist_3_link">
        <visual>
            <geometry>
                <mesh filename="package://ur_description/meshes/ur5/visual/wrist3.dae" />
            </geometry>
            <material name="LightGrey">
                <color rgba="0.7 0.7 0.7 1.0" />
            </material>
        </visual>
        <collision>
            <geometry>
                <mesh filename="package://ur_description/meshes/ur5/collision/wrist3.stl" />
            </geometry>
        </collision>
        <inertial>
            <mass value="0.01" />
            <origin rpy="1.5707963267948966 0 0" xyz="0.0 0.06505 0.0" />
            <inertia ixx="8.469589112163e-05" ixy="0.0" ixz="0.0" iyy="8.469589112163e-05" iyz="0.0" izz="0.0001321171875" />
        </inertial>
    </link>
    <joint name="ee_fixed_joint" type="fixed">
        <parent link="wrist_3_link" />
        <child link="ee_link" />
        <origin rpy="0.0 0.0 1.5707963267948966" xyz="0.0 0.0823 0.0" />
    </joint>
    <link name="ee_link">
        <collision>
            <geometry>
                <box size="0.01 0.01 0.01" />
            </geometry>
            <origin rpy="0 0 0" xyz="-0.01 0 0" />
        </collision>
        <inertial>
            <mass value="0.1" />
            <origin rpy="0 0 0" xyz="0 0 0" />
            <inertia ixx="0.03" ixy="0.0" ixz="0.0" iyy="0.03" iyz="0.0" izz="0.03" />
        </inertial>
    </link>
    <transmission name="shoulder_pan_trans">
        <type>transmission_interface/SimpleTransmission</type>
        <joint name="shoulder_pan_joint">
            <hardwareInterface>hardware_interface/EffortJointInterface</hardwareInterface>
        </joint>
        <actuator name="shoulder_pan_motor">
            <mechanicalReduction>1</mechanicalReduction>
            <hardwareInterface>hardware_interface/EffortJointInterface</hardwareInterface>
        </actuator>
    </transmission>
    <transmission name="shoulder_lift_trans">
        <type>transmission_interface/SimpleTransmission</type>
        <joint name="shoulder_lift_joint">
            <hardwareInterface>hardware_interface/EffortJointInterface</hardwareInterface>
        </joint>
        <actuator name="shoulder_lift_motor">
            <mechanicalReduction>1</mechanicalReduction>
            <hardwareInterface>hardware_interface/EffortJointInterface</hardwareInterface>
        </actuator>
    </transmission>
    <transmission name="elbow_trans">
        <type>transmission_interface/SimpleTransmission</type>
        <joint name="elbow_joint">
            <hardwareInterface>hardware_interface/EffortJointInterface</hardwareInterface>
        </joint>
        <actuator name="elbow_motor">
            <mechanicalReduction>1</mechanicalReduction>
            <hardwareInterface>hardware_interface/EffortJointInterface</hardwareInterface>
        </actuator>
    </transmission>
    <transmission name="wrist_1_trans">
        <type>transmission_interface/SimpleTransmission</type>
        <joint name="wrist_1_joint">
            <hardwareInterface>hardware_interface/EffortJointInterface</hardwareInterface>
        </joint>
        <actuator name="wrist_1_motor">
            <mechanicalReduction>1</mechanicalReduction>
            <hardwareInterface>hardware_interface/EffortJointInterface</hardwareInterface>
        </actuator>
    </transmission>
    <transmission name="wrist_2_trans">
        <type>transmission_interface/SimpleTransmission</type>
        <joint name="wrist_2_joint">
            <hardwareInterface>hardware_interface/EffortJointInterface</hardwareInterface>
        </joint>
        <actuator name="wrist_2_motor">
            <mechanicalReduction>1</mechanicalReduction>
            <hardwareInterface>hardware_interface/EffortJointInterface</hardwareInterface>
        </actuator>
    </transmission>
    <transmission name="wrist_3_trans">
        <type>transmission_interface/SimpleTransmission</type>
        <joint name="wrist_3_joint">
            <hardwareInterface>hardware_interface/EffortJointInterface</hardwareInterface>
        </joint>
        <actuator name="wrist_3_motor">
            <mechanicalReduction>1</mechanicalReduction>
            <hardwareInterface>hardware_interface/EffortJointInterface</hardwareInterface>
        </actuator>
    </transmission>
    <gazebo reference="shoulder_link">
        <selfCollide>true</selfCollide>
    </gazebo>
    <gazebo reference="upper_arm_link">
        <selfCollide>true</selfCollide>
    </gazebo>
    <gazebo reference="forearm_link">
        <selfCollide>true</selfCollide>
    </gazebo>
    <gazebo reference="wrist_1_link">
        <selfCollide>true</selfCollide>
    </gazebo>
    <gazebo reference="wrist_3_link">
        <selfCollide>true</selfCollide>
    </gazebo>
    <gazebo reference="wrist_2_link">
        <selfCollide>true</selfCollide>
    </gazebo>
    <gazebo reference="ee_link">
        <selfCollide>true</selfCollide>
    </gazebo>
    <!-- ROS base_link to UR 'Base' Coordinates transform -->
    <link name="base" />
    <joint name="base_link-base_fixed_joint" type="fixed">
        <!-- NOTE: this rotation is only needed as long as base_link itself is
                 not corrected wrt the real robot (ie: rotated over 180
                 degrees)
      -->
        <origin rpy="0 0 -3.141592653589793" xyz="0 0 0" />
        <parent link="chassis" />
        <child link="base" />
    </joint>
    <!-- Frame coincident with all-zeros TCP on UR controller -->
    <link name="tool0" />
    <joint name="wrist_3_link-tool0_fixed_joint" type="fixed">
        <origin rpy="-1.5707963267948966 0 0" xyz="0 0.0823 0" />
        <parent link="wrist_3_link" />
        <child link="tool0" />
    </joint>
    <!--joint name="world_joint" type="fixed">
    <parent link="base_footprint"/>
    <child link="base_link"/>
    <origin rpy="0.0 0.0 0.0" xyz="0.0 0.0 0.0"/>
  </joint-->
    <!-- Robotiq Coupler -->
    <!--  + Height added by the coupler: 8mm -->
    <!--  + Reference frame: at the middle (4mm) -->
    <link name="robotiq_coupler">
        <visual>
            <geometry>
                <mesh filename="package://robotiq_description/meshes/robotiq_85_coupler.stl" />
            </geometry>
            <material name="flat_black" />
        </visual>
        <collision>
            <geometry>
                <mesh filename="package://robotiq_description/meshes/robotiq_85_coupler.stl" />
            </geometry>
        </collision>
        <inertial>
            <origin rpy="0 0 0" xyz="2.073e-05   1.45286e-03  -1.1049e-03" />
            <mass value="0.01" />
            <inertia ixx="6.69695624e-05" ixy="5.21511788e-09" ixz="-2.74383009e-08" iyy="7.85088161e-05" iyz="5.41105193e-07" izz="1.41819717e-04" />
        </inertial>
    </link>
    <joint name="robotiq_coupler_joint" type="fixed">
        <origin rpy="0 0 -1.5707963267948966" xyz="0 0 0.004" />
        <parent link="tool0" />
        <child link="robotiq_coupler" />
    </joint>
    <gazebo reference="robotiq_coupler">
        <mu1>0.9</mu1>
        <mu2>0.9</mu2>
    </gazebo>
    <!-- Equivalent to the OpenRAVE manipulator denso_robotiq_85_gripper -->
    <!-- <link name="denso_robotiq_85_gripper" /> -->
    <!-- <joint name="manipulator_dummy_joint" type="fixed"> -->
    <!--   <origin xyz="0 0 0.1441" rpy="0 0 0" /> -->
    <!--   <parent link="robotiq_coupler"/> -->
    <!--   <child link="denso_robotiq_85_gripper"/> -->
    <!-- </joint> -->
    <joint name="robotiq_85_base_joint" type="fixed">
        <parent link="robotiq_coupler" />
        <child link="robotiq_85_base_link" />
        <origin rpy="0 -1.5707963267948966 3.141592653589793" xyz="0 0 0.004" />
    </joint>
    <link name="robotiq_85_base_link">
        <visual>
            <geometry>
                <mesh filename="package://robotiq_description/meshes/visual/robotiq_85_base_link.dae" />
            </geometry>
        </visual>
        <collision>
            <geometry>
                <mesh filename="package://robotiq_description/meshes/collision/robotiq_85_base_link.stl" />
            </geometry>
        </collision>
        <inertial>
            <mass value="0.01" />
            <origin rpy="0 0 0" xyz="0.0 0.0 0.0" />
            <inertia ixx="0.000380" ixy="0.000000" ixz="0.000000" iyx="0.000000" iyy="0.001110" iyz="0.000000" izx="0.000000" izy="0.000000" izz="0.001171" />
        </inertial>
    </link>
    <joint name="robotiq_85_left_knuckle_joint" type="revolute">
        <parent link="robotiq_85_base_link" />
        <child link="robotiq_85_left_knuckle_link" />
        <axis xyz="0 0 1" />
        <origin rpy="3.141592653589793 0.0 0.0" xyz="0.05490451627 0.03060114443 0.0" />
        <limit effort="1000" lower="0.0" upper="0.80285" velocity="0.5" />
    </joint>
    <joint name="robotiq_85_right_knuckle_joint" type="continuous">
        <parent link="robotiq_85_base_link" />
        <child link="robotiq_85_right_knuckle_link" />
        <axis xyz="0 0 1" />
        <origin rpy="0.0 0.0 0.0" xyz="0.05490451627 -0.03060114443 0.0" />
        <limit effort="1000" lower="-3.14" upper="3.14" velocity="100.0" />
        <mimic joint="robotiq_85_left_knuckle_joint" />
    </joint>
    <link name="robotiq_85_left_knuckle_link">
        <visual>
            <geometry>
                <mesh filename="package://robotiq_description/meshes/visual/robotiq_85_knuckle_link.dae" />
            </geometry>
        </visual>
        <collision>
            <geometry>
                <mesh filename="package://robotiq_description/meshes/collision/robotiq_85_knuckle_link.stl" />
            </geometry>
        </collision>
        <inertial>
            <mass value="0.01" />
            <origin rpy="0 0 0" xyz="0.0 0.0 0.0" />
            <inertia ixx="0.000009" ixy="-0.000001" ixz="0.000000" iyx="-0.000001" iyy="0.000001" iyz="0.000000" izx="0.000000" izy="0.000000" izz="0.000010" />
        </inertial>
    </link>
    <link name="robotiq_85_right_knuckle_link">
        <visual>
            <geometry>
                <mesh filename="package://robotiq_description/meshes/visual/robotiq_85_knuckle_link.dae" />
            </geometry>
        </visual>
        <collision>
            <geometry>
                <mesh filename="package://robotiq_description/meshes/collision/robotiq_85_knuckle_link.stl" />
            </geometry>
        </collision>
        <inertial>
            <mass value="0.01" />
            <origin rpy="0 0 0" xyz="0.0 0.0 0.0" />
            <inertia ixx="0.000009" ixy="-0.000001" ixz="0.000000" iyx="-0.000001" iyy="0.000001" iyz="0.000000" izx="0.000000" izy="0.000000" izz="0.000010" />
        </inertial>
    </link>
    <joint name="robotiq_85_left_finger_joint" type="fixed">
        <parent link="robotiq_85_left_knuckle_link" />
        <child link="robotiq_85_left_finger_link" />
        <origin rpy="0 0 0" xyz="-0.00408552455 -0.03148604435 0.0" />
    </joint>
    <joint name="robotiq_85_right_finger_joint" type="fixed">
        <parent link="robotiq_85_right_knuckle_link" />
        <child link="robotiq_85_right_finger_link" />
        <origin rpy="0 0 0" xyz="-0.00408552455 -0.03148604435 0.0" />
    </joint>
    <link name="robotiq_85_left_finger_link">
        <visual>
            <geometry>
                <mesh filename="package://robotiq_description/meshes/visual/robotiq_85_finger_link.dae" />
            </geometry>
        </visual>
        <collision>
            <geometry>
                <mesh filename="package://robotiq_description/meshes/collision/robotiq_85_finger_link.stl" />
            </geometry>
        </collision>
        <inertial>
            <mass value="0.01" />
            <origin rpy="0 0 0" xyz="0.0 0.0 0.0" />
            <inertia ixx="0.000003" ixy="-0.000002" ixz="0.000000" iyx="-0.000002" iyy="0.000021" iyz="0.000000" izx="0.000000" izy="0.000000" izz="0.000020" />
        </inertial>
    </link>
    <link name="robotiq_85_right_finger_link">
        <visual>
            <geometry>
                <mesh filename="package://robotiq_description/meshes/visual/robotiq_85_finger_link.dae" />
            </geometry>
        </visual>
        <collision>
            <geometry>
                <mesh filename="package://robotiq_description/meshes/collision/robotiq_85_finger_link.stl" />
            </geometry>
        </collision>
        <inertial>
            <mass value="0.01" />
            <origin rpy="0 0 0" xyz="0.0 0.0 0.0" />
            <inertia ixx="0.000003" ixy="-0.000002" ixz="0.000000" iyx="-0.000002" iyy="0.000021" iyz="0.000000" izx="0.000000" izy="0.000000" izz="0.000020" />
        </inertial>
    </link>
    <joint name="robotiq_85_left_inner_knuckle_joint" type="continuous">
        <parent link="robotiq_85_base_link" />
        <child link="robotiq_85_left_inner_knuckle_link" />
        <axis xyz="0 0 1" />
        <origin rpy="3.141592653589793 0.0 0.0" xyz="0.06142 0.0127 0" />
        <limit effort="0.1" lower="-3.14" upper="3.14" velocity="100.0" />
        <mimic joint="robotiq_85_left_knuckle_joint" offset="0" />
    </joint>
    <joint name="robotiq_85_right_inner_knuckle_joint" type="continuous">
        <parent link="robotiq_85_base_link" />
        <child link="robotiq_85_right_inner_knuckle_link" />
        <axis xyz="0 0 1" />
        <origin rpy="0 0 0" xyz="0.06142 -0.0127 0" />
        <limit effort="0.1" lower="-3.14" upper="3.14" velocity="100.0" />
        <mimic joint="robotiq_85_left_knuckle_joint" offset="0" />
    </joint>
    <link name="robotiq_85_left_inner_knuckle_link">
        <visual>
            <geometry>
                <mesh filename="package://robotiq_description/meshes/visual/robotiq_85_inner_knuckle_link.dae" />
            </geometry>
        </visual>
        <collision>
            <geometry>
                <mesh filename="package://robotiq_description/meshes/collision/robotiq_85_inner_knuckle_link.stl" />
            </geometry>
        </collision>
        <inertial>
            <mass value="0.01" />
            <origin rpy="0 0 0" xyz="0.0 0.0 0.0" />
            <inertia ixx="0.000039" ixy="0.000000" ixz="0.000000" iyx="0.000000" iyy="0.000005" iyz="0.000000" izx="0.000000" izy="0.000000" izz="0.000035" />
        </inertial>
    </link>
    <link name="robotiq_85_right_inner_knuckle_link">
        <visual>
            <geometry>
                <mesh filename="package://robotiq_description/meshes/visual/robotiq_85_inner_knuckle_link.dae" />
            </geometry>
        </visual>
        <collision>
            <geometry>
                <mesh filename="package://robotiq_description/meshes/collision/robotiq_85_inner_knuckle_link.stl" />
            </geometry>
        </collision>
        <inertial>
            <mass value="0.01" />
            <origin rpy="0 0 0" xyz="0.0 0.0 0.0" />
            <inertia ixx="0.000039" ixy="0.000000" ixz="0.000000" iyx="0.000000" iyy="0.000005" iyz="0.000000" izx="0.000000" izy="0.000000" izz="0.000035" />
        </inertial>
    </link>
    <joint name="robotiq_85_left_finger_tip_joint" type="continuous">
        <parent link="robotiq_85_left_inner_knuckle_link" />
        <child link="robotiq_85_left_finger_tip_link" />
        <axis xyz="0 0 1" />
        <origin rpy="0.0 0.0 0.0" xyz="0.04303959807 -0.03759940821 0.0" />
        <limit effort="0.1" lower="-3.14" upper="3.14" velocity="100.0" />
        <mimic joint="robotiq_85_left_knuckle_joint" multiplier="-1" />
    </joint>
    <joint name="robotiq_85_right_finger_tip_joint" type="continuous">
        <parent link="robotiq_85_right_inner_knuckle_link" />
        <child link="robotiq_85_right_finger_tip_link" />
        <axis xyz="0 0 1" />
        <origin rpy="0.0 0.0 0.0" xyz="0.04303959807 -0.03759940821  0.0" />
        <limit effort="0.1" lower="-3.14" upper="3.14" velocity="100.0" />
        <mimic joint="robotiq_85_left_knuckle_joint" multiplier="-1" />
    </joint>
    <link name="robotiq_85_left_finger_tip_link">
        <visual>
            <geometry>
                <mesh filename="package://robotiq_description/meshes/visual/robotiq_85_finger_tip_link.dae" />
            </geometry>
        </visual>
        <collision>
            <geometry>
                <mesh filename="package://robotiq_description/meshes/collision/robotiq_85_finger_tip_link.stl" />
            </geometry>
        </collision>
        <inertial>
            <mass value="0.01" />
            <origin rpy="0 0 0" xyz="0.0 0.0 0.0" />
            <inertia ixx="0.000002" ixy="0.000000" ixz="0.000000" iyx="0.000000" iyy="0.000005" iyz="0.000000" izx="0.000000" izy="0.000000" izz="0.000006" />
        </inertial>
    </link>
    <link name="robotiq_85_right_finger_tip_link">
        <visual>
            <geometry>
                <mesh filename="package://robotiq_description/meshes/visual/robotiq_85_finger_tip_link.dae" />
            </geometry>
        </visual>
        <collision>
            <geometry>
                <mesh filename="package://robotiq_description/meshes/collision/robotiq_85_finger_tip_link.stl" />
            </geometry>
        </collision>
        <inertial>
            <mass value="0.01" />
            <origin rpy="0 0 0" xyz="0.0 0.0 0.0" />
            <inertia ixx="0.000002" ixy="0.000000" ixz="0.000000" iyx="0.000000" iyy="0.000005" iyz="0.000000" izx="0.000000" izy="0.000000" izz="0.000006" />
        </inertial>
    </link>
    <!-- Improve grasping physics -->
    <gazebo reference="robotiq_85_left_finger_tip_link">
        <kp>1000000.0</kp>
        <kd>1.0</kd>
        <mu1>1.0</mu1>
        <mu2>1.0</mu2>
        <minDepth>0.001</minDepth>
    </gazebo>
    <gazebo reference="robotiq_85_right_finger_tip_link">
        <kp>1000000.0</kp>
        <kd>1.0</kd>
        <mu1>1.0</mu1>
        <mu2>1.0</mu2>
        <minDepth>0.001</minDepth>
    </gazebo>
    <transmission name="robotiq_85_left_knuckle_trans">
        <type>transmission_interface/SimpleTransmission</type>
        <joint name="robotiq_85_left_knuckle_joint">
            <hardwareInterface>hardware_interface/EffortJointInterface</hardwareInterface>
            <!-- <hardwareInterface>EffortJointInterface</hardwareInterface> -->
        </joint>
        <actuator name="robotiq_85_left_knuckle_motor">
            <mechanicalReduction>1</mechanicalReduction>
            <hardwareInterface>hardware_interface/EffortJointInterface</hardwareInterface>
            <!-- <hardwareInterface>EfforJointInterface</hardwareInterface> -->
        </actuator>
    </transmission>
    <!-- Mimic joints -->
    <gazebo>
        <plugin filename="libgazebo_mimic_joint_plugin.so" name="mimic_robotiq_85_1">
            <joint>robotiq_85_left_knuckle_joint</joint>
            <mimicJoint>robotiq_85_right_knuckle_joint</mimicJoint>
        </plugin>
        <plugin filename="libgazebo_mimic_joint_plugin.so" name="mimic_robotiq_85_2">
            <joint>robotiq_85_left_knuckle_joint</joint>
            <mimicJoint>robotiq_85_left_inner_knuckle_joint</mimicJoint>
        </plugin>
        <plugin filename="libgazebo_mimic_joint_plugin.so" name="mimic_robotiq_85_3">
            <joint>robotiq_85_left_knuckle_joint</joint>
            <mimicJoint>robotiq_85_right_inner_knuckle_joint</mimicJoint>
        </plugin>
        <plugin filename="libgazebo_mimic_joint_plugin.so" name="mimic_robotiq_85_4">
            <joint>robotiq_85_left_knuckle_joint</joint>
            <mimicJoint>robotiq_85_left_finger_tip_joint</mimicJoint>
            <multiplier>-1.0</multiplier>
            <offset>0.0</offset>
        </plugin>
        <plugin filename="libgazebo_mimic_joint_plugin.so" name="mimic_robotiq_85_5">
            <joint>robotiq_85_left_knuckle_joint</joint>
            <mimicJoint>robotiq_85_right_finger_tip_joint</mimicJoint>
            <multiplier>-1.0</multiplier>
            <offset>0.0</offset>
        </plugin>
    </gazebo>
    <!-- Gazebo FT sensor plugin -->
    <gazebo reference="wrist_3_joint">
        <provideFeedback>true</provideFeedback>
    </gazebo>
    <gazebo>
        <plugin filename="libgazebo_ros_ft_sensor.so" name="ft_sensor_plugin">
            <updateRate>250.0</updateRate>
            <topicName>ft_sensor/raw</topicName>
            <gaussianNoise>0.0</gaussianNoise>
            <jointName>wrist_3_joint</jointName>
        </plugin>
    </gazebo>
    <!-- Gazebo grasping plugin -->
    <gazebo>
        <gripper name="gazebo_gripper">
            <grasp_check>
                <attach_steps>2</attach_steps>
                <!-- default: 20 -->
                <detach_steps>2</detach_steps>
                <!-- default: 40 -->
                <min_contact_count>3</min_contact_count>
            </grasp_check>
            <gripper_link>robotiq_85_left_finger_tip_link</gripper_link>
            <gripper_link>robotiq_85_right_finger_tip_link</gripper_link>
            <palm_link>robotiq_85_base_link</palm_link>
        </gripper>
    </gazebo>
    <transmission name="trans_robotiq_85_right_knuckle_joint">
        <type>transmission_interface/SimpleTransmission</type>
        <joint name="robotiq_85_right_knuckle_joint">
            <hardwareInterface>hardware_interface/EffortJointInterface</hardwareInterface>
        </joint>
        <actuator name="robotiq_85_right_knuckle_joint_motor">
            <hardwareInterface>hardware_interface/EffortJointInterface</hardwareInterface>
            <mechanicalReduction>1</mechanicalReduction>
        </actuator>
    </transmission>
    <transmission name="trans_robotiq_85_left_inner_knuckle_joint">
        <type>transmission_interface/SimpleTransmission</type>
        <joint name="robotiq_85_left_inner_knuckle_joint">
            <hardwareInterface>hardware_interface/EffortJointInterface</hardwareInterface>
        </joint>
        <actuator name="robotiq_85_left_inner_knuckle_joint_motor">
            <hardwareInterface>hardware_interface/EffortJointInterface</hardwareInterface>
            <mechanicalReduction>1</mechanicalReduction>
        </actuator>
    </transmission>
    <transmission name="trans_robotiq_85_right_inner_knuckle_joint">
        <type>transmission_interface/SimpleTransmission</type>
        <joint name="robotiq_85_right_inner_knuckle_joint">
            <hardwareInterface>hardware_interface/EffortJointInterface</hardwareInterface>
        </joint>
        <actuator name="robotiq_85_right_inner_knuckle_joint_motor">
            <hardwareInterface>hardware_interface/EffortJointInterface</hardwareInterface>
            <mechanicalReduction>1</mechanicalReduction>
        </actuator>
    </transmission>
    <transmission name="trans_robotiq_85_left_finger_tip_joint">
        <type>transmission_interface/SimpleTransmission</type>
        <joint name="robotiq_85_left_finger_tip_joint">
            <hardwareInterface>hardware_interface/EffortJointInterface</hardwareInterface>
        </joint>
        <actuator name="robotiq_85_left_finger_tip_joint_motor">
            <hardwareInterface>hardware_interface/EffortJointInterface</hardwareInterface>
            <mechanicalReduction>1</mechanicalReduction>
        </actuator>
    </transmission>
    <transmission name="trans_robotiq_85_right_finger_tip_joint">
        <type>transmission_interface/SimpleTransmission</type>
        <joint name="robotiq_85_right_finger_tip_joint">
            <hardwareInterface>hardware_interface/EffortJointInterface</hardwareInterface>
        </joint>
        <actuator name="robotiq_85_right_finger_tip_joint_motor">
            <hardwareInterface>hardware_interface/EffortJointInterface</hardwareInterface>
            <mechanicalReduction>1</mechanicalReduction>
        </actuator>
    </transmission>
    <root name="sensor_kinect">
        <gazebo reference="camera_depth_frame">
            <sensor name="camera1" type="depth">
                <always_on>true</always_on>
                <update_rate>20.0</update_rate>
                <camera>
                    <horizontal_fov>1.0471975511965976</horizontal_fov>
                    <image>
                        <format>R8G8B8</format>
                        <width>640</width>
                        <height>480</height>
                    </image>
                    <clip>
                        <near>0.05</near>
                        <far>8.0</far>
                    </clip>
                </camera>
                <plugin filename="libgazebo_ros_openni_kinect.so" name="camera_depth_frame_kinect_controller">
                    <baseline>0.1</baseline>
                    <alwaysOn>true</alwaysOn>
                    <updateRate>10</updateRate>
                    <cameraName>camera1</cameraName>
                    <imageTopicName>rgb/image_raw</imageTopicName>
                    <cameraInfoTopicName>rgb/camera_info</cameraInfoTopicName>
                    <depthImageTopicName>depth/image_raw</depthImageTopicName>
                    <depthImageCameraInfoTopicName>depth/camera_info</depthImageCameraInfoTopicName>
                    <pointCloudTopicName>depth/points</pointCloudTopicName>
                    <frameName>camera_depth_optical_frame</frameName>
                    <pointCloudCutoff>0.3</pointCloudCutoff>
                    <distortion_k1>0.0</distortion_k1>
                    <distortion_k2>0.0</distortion_k2>
                    <distortion_k3>0.0</distortion_k3>
                    <distortion_t1>0.0</distortion_t1>
                    <distortion_t2>0.0</distortion_t2>
                    <!--
          <CxPrime>0</CxPrime>
          <Cx>0</Cx>
          <Cy>0</Cy>
          <focalLength>0</focalLength>
          <hackBaseline>0</hackBaseline>
      -->
                </plugin>
            </sensor>
        </gazebo>
    </root>
    <joint name="camera_rgb_joint" type="fixed">
        <origin rpy="0 1.25 -1.54" xyz="0 0 2" />
        <parent link="chassis" />
        <child link="camera_rgb_frame" />
    </joint>
    <link name="camera_rgb_frame">
        <inertial>
            <mass value="0.001" />
            <origin xyz="0 0 0" />
            <inertia ixx="0.0001" ixy="0.0" ixz="0.0" iyy="0.0001" iyz="0.0" izz="0.0001" />
        </inertial>
    </link>
    <joint name="camera_rgb_optical_joint" type="fixed">
        <origin rpy="-1.5707963267948966 0 -1.5707963267948966" xyz="0 0 0" />
        <parent link="camera_rgb_frame" />
        <child link="camera_rgb_optical_frame" />
    </joint>
    <link name="camera_rgb_optical_frame">
        <inertial>
            <mass value="0.001" />
            <origin xyz="0 0 0" />
            <inertia ixx="0.0001" ixy="0.0" ixz="0.0" iyy="0.0001" iyz="0.0" izz="0.0001" />
        </inertial>
    </link>
    <joint name="camera_joint" type="fixed">
        <origin rpy="0 0 0" xyz="-0.031 0 -0.016" />
        <parent link="camera_rgb_frame" />
        <child link="camera_link" />
    </joint>
    <link name="camera_link">
        <visual>
            <origin rpy="0 0 1.5707963267948966" xyz="0 0 0" />
            <geometry>
                <mesh filename="package://common_sensors/meshes/sensors/kinect.dae" />
            </geometry>
        </visual>
        <collision>
            <origin rpy="0 0 0" xyz="0.0 0.0 0.0" />
            <geometry>
                <box size="0.07271 0.27794 0.073" />
            </geometry>
        </collision>
        <inertial>
            <mass value="0.001" />
            <origin xyz="0 0 0" rpy="0 0 0" />
            <inertia ixx="0.0001" ixy="0.0" ixz="0.0" iyy="0.0001" iyz="0.0" izz="0.0001" />
        </inertial>
    </link>
    <!-- The fixed joints & links below are usually published by static_transformers launched by the OpenNi launch 
		 files. However, for Gazebo simulation we need them, so we add them here.
		 (Hence, don't publish them additionally!) -->
    <joint name="camera_depth_joint" type="fixed">
        <origin rpy="0 0 0" xyz="0 0 0" />
        <parent link="camera_rgb_frame" />
        <child link="camera_depth_frame" />
    </joint>
    <link name="camera_depth_frame">
        <inertial>
            <mass value="0.001" />
            <origin xyz="0 0 0" />
            <inertia ixx="0.0001" ixy="0.0" ixz="0.0" iyy="0.0001" iyz="0.0" izz="0.0001" />
        </inertial>
    </link>
    <joint name="camera_depth_optical_joint" type="fixed">
        <origin rpy="-1.5707963267948966 0 -1.5707963267948966" xyz="0 0 0" />
        <parent link="camera_depth_frame" />
        <child link="camera_depth_optical_frame" />
    </joint>
    <link name="camera_depth_optical_frame">
        <inertial>
            <mass value="0.001" />
            <origin xyz="0 0 0" />
            <inertia ixx="0.0001" ixy="0.0" ixz="0.0" iyy="0.0001" iyz="0.0" izz="0.0001" />
        </inertial>
    </link>
</robot>

